Workbook

Sheet inventory_transactions(lookups)
A1: Order_ID | B1: Date | C1: SKU | D1: Qty_Sold | E1: Location | F1: Staff_ID | G1: Revenue | H1: Lead_Time | I1: Risk_Level | J1: Category | K1: Stock_Level
A2: ORD-501 | B2: 9/22/2025 | C2: SURG-P-02 | D2: 18 | E2: North | F2: Optician_A | G2: 1530 | H2: 30 | I2: Medium Risk | J2: =_xlfn.XLOOKUP('inventory_transactions(lookups)'!C2,'product_masterlist(ifs)'!A:A,'product_masterlist(ifs)'!C:C,,0) -> Surgical | K2: =VLOOKUP(C2,'product_masterlist(ifs)'!A:I,7,FALSE) -> 40
A3: ORD-502 | B3: 8/16/2025 | C3: FRM-M-10 | D3: 4 | E3: North | F3: Optician_C | G3: 180 | H3: 30 | I3: Medium Risk | J3: =_xlfn.XLOOKUP(C3,'product_masterlist(ifs)'!A:A,'product_masterlist(ifs)'!C:C,"N/A",0) -> Frames | K3: =VLOOKUP(C3,'product_masterlist(ifs)'!A:I,7,FALSE) -> 45
A4: ORD-503 | B4: 45840 | C4: SURG-P-02 | D4: 13 | E4: East | F4: Optician_A | G4: 1105 | H4: 30 | I4: Medium Risk | J4: =_xlfn.XLOOKUP(C4,'product_masterlist(ifs)'!A:A,'product_masterlist(ifs)'!C:C,"N/A",0) -> Surgical | K4: =VLOOKUP(C4,'product_masterlist(ifs)'!A:I,7,FALSE) -> 40
A5: ORD-504 | B5: 45937 | C5: SURG-P-02 | D5: 16 | E5: West | F5: Surgeon_K | G5: 1360 | H5: 30 | I5: Medium Risk | J5: =_xlfn.XLOOKUP(C5,'product_masterlist(ifs)'!A:A,'product_masterlist(ifs)'!C:C,"N/A",0) -> Surgical | K5: =VLOOKUP(C5,'product_masterlist(ifs)'!A:I,7,FALSE) -> 40
A6: ORD-505 | B6: 5/29/2025 | C6: LENS-D-01 | D6: 7 | E6: West | F6: Optician_A | G6: 87.5 | H6: 14 | I6: Low Risk | J6: =_xlfn.XLOOKUP(C6,'product_masterlist(ifs)'!A:A,'product_masterlist(ifs)'!C:C,"N/A",0) -> Contact Lenses | K6: =VLOOKUP(C6,'product_masterlist(ifs)'!A:I,7,FALSE) -> 450
A7: ORD-506 | B7: 1/26/2025 | C7: SURG-P-02 | D7: 24 | E7: East | F7: Optician_B | G7: 2040 | H7: 30 | I7: Medium Risk | J7: =_xlfn.XLOOKUP(C7,'product_masterlist(ifs)'!A:A,'product_masterlist(ifs)'!C:C,"N/A",0) -> Surgical | K7: =VLOOKUP(C7,'product_masterlist(ifs)'!A:I,7,FALSE) -> 40
A8: ORD-507 | B8: 45999 | C8: SURG-L-01 | D8: 10 | E8: North | F8: Optician_C | G8: 1500 | H8: 45 | I8: High Risk | J8: =_xlfn.XLOOKUP(C8,'product_masterlist(ifs)'!A:A,'product_masterlist(ifs)'!C:C,"N/A",0) -> Surgical | K8: =VLOOKUP(C8,'product_masterlist(ifs)'!A:I,7,FALSE) -> 15
A9: ORD-508 | B9: 4/24/2025 | C9: LENS-D-01 | D9: 8 | E9: South | F9: Optician_C | G9: 100 | H9: 14 | I9: Low Risk | J9: =_xlfn.XLOOKUP(C9,'product_masterlist(ifs)'!A:A,'product_masterlist(ifs)'!C:C,"N/A",0) -> Contact Lenses | K9: =VLOOKUP(C9,'product_masterlist(ifs)'!A:I,7,FALSE) -> 450
A10: ORD-509 | B10: 5/21/2025 | C10: LENS-D-01 | D10: 3 | E10: South | F10: Optician_A | G10: 37.5 | H10: 14 | I10: Low Risk | J10: =_xlfn.XLOOKUP(C10,'product_masterlist(ifs)'!A:A,'product_masterlist(ifs)'!C:C,"N/A",0) -> Contact Lenses | K10: =VLOOKUP(C10,'product_masterlist(ifs)'!A:I,7,FALSE) -> 450
A11: ORD-510 | B11: 45699 | C11: LENS-M-02 | D11: 21 | E11: West | F11: Optician_C | G11: 525 | H11: 21 | I11: Medium Risk | J11: =_xlfn.XLOOKUP(C11,'product_masterlist(ifs)'!A:A,'product_masterlist(ifs)'!C:C,"N/A",0) -> Contact Lenses | K11: =VLOOKUP(C11,'product_masterlist(ifs)'!A:I,7,FALSE) -> 120
A12: ORD-511 | B12: 7/30/2025 | C12: LENS-D-01 | D12: 7 | E12: West | F12: Optician_B | G12: 87.5 | H12: 14 | I12: Low Risk | J12: =_xlfn.XLOOKUP(C12,'product_masterlist(ifs)'!A:A,'product_masterlist(ifs)'!C:C,"N/A",0) -> Contact Lenses | K12: =VLOOKUP(C12,'product_masterlist(ifs)'!A:I,7,FALSE) -> 450
A13: ORD-512 | B13: 1/20/2025 | C13: LENS-D-01 | D13: 11 | E13: North | F13: Optician_A | G13: 137.5 | H13: 14 | I13: Low Risk | J13: =_xlfn.XLOOKUP(C13,'product_masterlist(ifs)'!A:A,'product_masterlist(ifs)'!C:C,"N/A",0) -> Contact Lenses | K13: =VLOOKUP(C13,'product_masterlist(ifs)'!A:I,7,FALSE) -> 450
A14: ORD-513 | B14: 45908 | C14: FRM-M-10 | D14: 8 | E14: East | F14: Optician_C | G14: 360 | H14: 30 | I14: Medium Risk | J14: =_xlfn.XLOOKUP(C14,'product_masterlist(ifs)'!A:A,'product_masterlist(ifs)'!C:C,"N/A",0) -> Frames | K14: =VLOOKUP(C14,'product_masterlist(ifs)'!A:I,7,FALSE) -> 45
A15: ORD-514 | B15: 46003 | C15: SURG-P-02 | D15: 25 | E15: South | F15: Optician_C | G15: 2125 | H15: 30 | I15: Medium Risk | J15: =_xlfn.XLOOKUP(C15,'product_masterlist(ifs)'!A:A,'product_masterlist(ifs)'!C:C,"N/A",0) -> Surgical | K15: =VLOOKUP(C15,'product_masterlist(ifs)'!A:I,7,FALSE) -> 40
A16: ORD-515 | B16: 45750 | C16: SURG-L-01 | D16: 1 | E16: East | F16: Optician_C | G16: 150 | H16: 45 | I16: High Risk | J16: =_xlfn.XLOOKUP(C16,'product_masterlist(ifs)'!A:A,'product_masterlist(ifs)'!C:C,"N/A",0) -> Surgical | K16: =VLOOKUP(C16,'product_masterlist(ifs)'!A:I,7,FALSE) -> 15
A17: ORD-516 | B17: 12/26/2025 | C17: SOL-S-01 | D17: 19 | E17: North | F17: Optician_A | G17: 80.75 | H17: 7 | I17: Low Risk | J17: =_xlfn.XLOOKUP(C17,'product_masterlist(ifs)'!A:A,'product_masterlist(ifs)'!C:C,"N/A",0) -> Solutions | K17: =VLOOKUP(C17,'product_masterlist(ifs)'!A:I,7,FALSE) -> 800
A18: ORD-517 | B18: 45757 | C18: SURG-L-01 | D18: 23 | E18: West | F18: Optician_B | G18: 3450 | H18: 45 | I18: High Risk | J18: =_xlfn.XLOOKUP(C18,'product_masterlist(ifs)'!A:A,'product_masterlist(ifs)'!C:C,"N/A",0) -> Surgical | K18: =VLOOKUP(C18,'product_masterlist(ifs)'!A:I,7,FALSE) -> 15
A19: ORD-518 | B19: 45845 | C19: FRM-M-10 | D19: 19 | E19: West | F19: Optician_B | G19: 855 | H19: 30 | I19: Medium Risk | J19: =_xlfn.XLOOKUP(C19,'product_masterlist(ifs)'!A:A,'product_masterlist(ifs)'!C:C,"N/A",0) -> Frames | K19: =VLOOKUP(C19,'product_masterlist(ifs)'!A:I,7,FALSE) -> 45
A20: ORD-519 | B20: 5/22/2025 | C20: FRM-M-10 | D20: 16 | E20: South | F20: Optician_A | G20: 720 | H20: 30 | I20: Medium Risk | J20: =_xlfn.XLOOKUP(C20,'product_masterlist(ifs)'!A:A,'product_masterlist(ifs)'!C:C,"N/A",0) -> Frames | K20: =VLOOKUP(C20,'product_masterlist(ifs)'!A:I,7,FALSE) -> 45
A21: ORD-520 | B21: 4/28/2025 | C21: SURG-L-01 | D21: 6 | E21: South | F21: Optician_B | G21: 900 | H21: 45 | I21: High Risk | J21: =_xlfn.XLOOKUP(C21,'product_masterlist(ifs)'!A:A,'product_masterlist(ifs)'!C:C,"N/A",0) -> Surgical | K21: =VLOOKUP(C21,'product_masterlist(ifs)'!A:I,7,FALSE) -> 15
A22: ORD-521 | B22: 10/27/2025 | C22: LENS-M-02 | D22: 12 | E22: South | F22: Surgeon_K | G22: 300 | H22: 21 | I22: Medium Risk | J22: =_xlfn.XLOOKUP(C22,'product_masterlist(ifs)'!A:A,'product_masterlist(ifs)'!C:C,"N/A",0) -> Contact Lenses | K22: =VLOOKUP(C22,'product_masterlist(ifs)'!A:I,7,FALSE) -> 120
A23: ORD-522 | B23: 45940 | C23: FRM-M-10 | D23: 19 | E23: West | F23: Optician_B | G23: 855 | H23: 30 | I23: Medium Risk | J23: =_xlfn.XLOOKUP(C23,'product_masterlist(ifs)'!A:A,'product_masterlist(ifs)'!C:C,"N/A",0) -> Frames | K23: =VLOOKUP(C23,'product_masterlist(ifs)'!A:I,7,FALSE) -> 45
A24: ORD-523 | B24: 11/13/2025 | C24: SURG-L-01 | D24: 2 | E24: East | F24: Optician_A | G24: 300 | H24: 45 | I24: High Risk | J24: =_xlfn.XLOOKUP(C24,'product_masterlist(ifs)'!A:A,'product_masterlist(ifs)'!C:C,"N/A",0) -> Surgical | K24: =VLOOKUP(C24,'product_masterlist(ifs)'!A:I,7,FALSE) -> 15
A25: ORD-524 | B25: 6/22/2025 | C25: LENS-M-02 | D25: 24 | E25: West | F25: Optician_C | G25: 600 | H25: 21 | I25: Medium Risk | J25: =_xlfn.XLOOKUP(C25,'product_masterlist(ifs)'!A:A,'product_masterlist(ifs)'!C:C,"N/A",0) -> Contact Lenses | K25: =VLOOKUP(C25,'product_masterlist(ifs)'!A:I,7,FALSE) -> 120
A26: ORD-525 | B26: 45717 | C26: SURG-L-01 | D26: 25 | E26: West | F26: Optician_B | G26: 3750 | H26: 45 | I26: High Risk | J26: =_xlfn.XLOOKUP(C26,'product_masterlist(ifs)'!A:A,'product_masterlist(ifs)'!C:C,"N/A",0) -> Surgical | K26: =VLOOKUP(C26,'product_masterlist(ifs)'!A:I,7,FALSE) -> 15
A27: ORD-526 | B27: 45787 | C27: LENS-D-01 | D27: 24 | E27: North | F27: Optician_A | G27: 300 | H27: 14 | I27: Low Risk | J27: =_xlfn.XLOOKUP(C27,'product_masterlist(ifs)'!A:A,'product_masterlist(ifs)'!C:C,"N/A",0) -> Contact Lenses | K27: =VLOOKUP(C27,'product_masterlist(ifs)'!A:I,7,FALSE) -> 450
A28: ORD-527 | B28: 4/21/2025 | C28: LENS-D-01 | D28: 18 | E28: South | F28: Optician_A | G28: 225 | H28: 14 | I28: Low Risk | J28: =_xlfn.XLOOKUP(C28,'product_masterlist(ifs)'!A:A,'product_masterlist(ifs)'!C:C,"N/A",0) -> Contact Lenses | K28: =VLOOKUP(C28,'product_masterlist(ifs)'!A:I,7,FALSE) -> 450
A29: ORD-528 | B29: 45725 | C29: LENS-D-01 | D29: 2 | E29: East | F29: Optician_B | G29: 25 | H29: 14 | I29: Low Risk | J29: =_xlfn.XLOOKUP(C29,'product_masterlist(ifs)'!A:A,'product_masterlist(ifs)'!C:C,"N/A",0) -> Contact Lenses | K29: =VLOOKUP(C29,'product_masterlist(ifs)'!A:I,7,FALSE) -> 450
A30: ORD-529 | B30: 2/17/2025 | C30: SOL-S-01 | D30: 9 | E30: South | F30: Optician_A | G30: 38.25 | H30: 7 | I30: Low Risk | J30: =_xlfn.XLOOKUP(C30,'product_masterlist(ifs)'!A:A,'product_masterlist(ifs)'!C:C,"N/A",0) -> Solutions | K30: =VLOOKUP(C30,'product_masterlist(ifs)'!A:I,7,FALSE) -> 800
A31: ORD-530 | B31: 45911 | C31: SURG-P-02 | D31: 3 | E31: West | F31: Optician_B | G31: 255 | H31: 30 | I31: Medium Risk | J31: =_xlfn.XLOOKUP(C31,'product_masterlist(ifs)'!A:A,'product_masterlist(ifs)'!C:C,"N/A",0) -> Surgical | K31: =VLOOKUP(C31,'product_masterlist(ifs)'!A:I,7,FALSE) -> 40
A32: ORD-531 | B32: 45698 | C32: SURG-L-01 | D32: 8 | E32: West | F32: Optician_C | G32: 1200 | H32: 45 | I32: High Risk | J32: =_xlfn.XLOOKUP(C32,'product_masterlist(ifs)'!A:A,'product_masterlist(ifs)'!C:C,"N/A",0) -> Surgical | K32: =VLOOKUP(C32,'product_masterlist(ifs)'!A:I,7,FALSE) -> 15
A33: ORD-532 | B33: 45722 | C33: FRM-M-10 | D33: 9 | E33: North | F33: Surgeon_K | G33: 405 | H33: 30 | I33: Medium Risk | J33: =_xlfn.XLOOKUP(C33,'product_masterlist(ifs)'!A:A,'product_masterlist(ifs)'!C:C,"N/A",0) -> Frames | K33: =VLOOKUP(C33,'product_masterlist(ifs)'!A:I,7,FALSE) -> 45
A34: ORD-533 | B34: 8/23/2025 | C34: SURG-L-01 | D34: 18 | E34: South | F34: Surgeon_K | G34: 2700 | H34: 45 | I34: High Risk | J34: =_xlfn.XLOOKUP(C34,'product_masterlist(ifs)'!A:A,'product_masterlist(ifs)'!C:C,"N/A",0) -> Surgical | K34: =VLOOKUP(C34,'product_masterlist(ifs)'!A:I,7,FALSE) -> 15
A35: ORD-534 | B35: 45966 | C35: LENS-M-02 | D35: 7 | E35: East | F35: Optician_C | G35: 175 | H35: 21 | I35: Medium Risk | J35: =_xlfn.XLOOKUP(C35,'product_masterlist(ifs)'!A:A,'product_masterlist(ifs)'!C:C,"N/A",0) -> Contact Lenses | K35: =VLOOKUP(C35,'product_masterlist(ifs)'!A:I,7,FALSE) -> 120
A36: ORD-535 | B36: 1/31/2025 | C36: LENS-M-02 | D36: 6 | E36: North | F36: Optician_B | G36: 150 | H36: 21 | I36: Medium Risk | J36: =_xlfn.XLOOKUP(C36,'product_masterlist(ifs)'!A:A,'product_masterlist(ifs)'!C:C,"N/A",0) -> Contact Lenses | K36: =VLOOKUP(C36,'product_masterlist(ifs)'!A:I,7,FALSE) -> 120
A37: ORD-536 | B37: 45843 | C37: LENS-M-02 | D37: 21 | E37: West | F37: Surgeon_K | G37: 525 | H37: 21 | I37: Medium Risk | J37: =_xlfn.XLOOKUP(C37,'product_masterlist(ifs)'!A:A,'product_masterlist(ifs)'!C:C,"N/A",0) -> Contact Lenses | K37: =VLOOKUP(C37,'product_masterlist(ifs)'!A:I,7,FALSE) -> 120
A38: ORD-537 | B38: 45781 | C38: LENS-D-01 | D38: 24 | E38: South | F38: Optician_B | G38: 300 | H38: 14 | I38: Low Risk | J38: =_xlfn.XLOOKUP(C38,'product_masterlist(ifs)'!A:A,'product_masterlist(ifs)'!C:C,"N/A",0) -> Contact Lenses | K38: =VLOOKUP(C38,'product_masterlist(ifs)'!A:I,7,FALSE) -> 450
A39: ORD-538 | B39: 10/31/2025 | C39: SURG-P-02 | D39: 6 | E39: South | F39: Optician_C | G39: 510 | H39: 30 | I39: Medium Risk | J39: =_xlfn.XLOOKUP(C39,'product_masterlist(ifs)'!A:A,'product_masterlist(ifs)'!C:C,"N/A",0) -> Surgical | K39: =VLOOKUP(C39,'product_masterlist(ifs)'!A:I,7,FALSE) -> 40
A40: ORD-539 | B40: 8/31/2025 | C40: FRM-W-12 | D40: 9 | E40: East | F40: Optician_B | G40: 436.5 | H40: 30 | I40: Medium Risk | J40: =_xlfn.XLOOKUP(C40,'product_masterlist(ifs)'!A:A,'product_masterlist(ifs)'!C:C,"N/A",0) -> Frames | K40: =VLOOKUP(C40,'product_masterlist(ifs)'!A:I,7,FALSE) -> 180
...

Sheet product_masterlist(ifs)
A1: SKU | B1: Description | C1: Category | D1: Supplier | E1: Unit_Cost | F1: Lead_Time_Days | G1: Stock_Level | H1: Reorder_Point | I1: Total_Value | J1: Stock_Status
A2: LENS-D-01 | B2: Daily Contacts | C2: Contact Lenses | D2: ClearVision | E2: 12.5 | F2: 14 | G2: 450 | H2: 500 | I2: 5625 | J2: {=_xlfn.IFS(G2<H2,"Reorder",G2>2*H2,"Healthy",G2>=H2,"Low Stock")} -> Reorder
A3: LENS-M-02 | B3: Monthly Toric | C3: Contact Lenses | D3: ClearVision | E3: 25 | F3: 21 | G3: 120 | H3: 150 | I3: 3000 | J3: {=_xlfn.IFS(G3<H3,"Reorder",G3>2*H3,"Healthy",G3>=H3,"Low Stock")} -> Reorder
A4: FRM-M-10 | B4: Men's Aviator | C4: Frames | D4: OptiStyle | E4: 45 | F4: 30 | G4: 45 | H4: 50 | I4: 2025 | J4: {=_xlfn.IFS(G4<H4,"Reorder",G4>2*H4,"Healthy",G4>=H4,"Low Stock")} -> Reorder
A5: FRM-W-12 | B5: Women's Cat Eye | C5: Frames | D5: OptiStyle | E5: 48.5 | F5: 30 | G5: 180 | H5: 50 | I5: 8730 | J5: {=_xlfn.IFS(G5<H5,"Reorder",G5>2*H5,"Healthy",G5>=H5,"Low Stock")} -> Healthy
A6: SOL-S-01 | B6: Saline 300ml | C6: Solutions | D6: AquaDrop | E6: 4.25 | F6: 7 | G6: 800 | H6: 400 | I6: 3400 | J6: {=_xlfn.IFS(G6<H6,"Reorder",G6>2*H6,"Healthy",G6>=H6,"Low Stock")} -> Low Stock
A7: SURG-L-01 | B7: Intraocular Lens | C7: Surgical | D7: MedEye Tech | E7: 150 | F7: 45 | G7: 15 | H7: 20 | I7: 2250 | J7: {=_xlfn.IFS(G7<H7,"Reorder",G7>2*H7,"Healthy",G7>=H7,"Low Stock")} -> Reorder
A8: SURG-P-02 | B8: Phaco Tip | C8: Surgical | D8: MedEye Tech | E8: 85 | F8: 30 | G8: 40 | H8: 25 | I8: 3400 | J8: {=_xlfn.IFS(G8<H8,"Reorder",G8>2*H8,"Healthy",G8>=H8,"Low Stock")} -> Low Stock

Sheet product_summary (Hlookup)
A6: Table Information
A7: SKU | B7: LENS-D-01 | C7: LENS-M-02 | D7: FRM-M-10 | E7: FRM-W-12 | F7: SOL-S-01 | G7: SURG-L-01 | H7: SURG-P-02
A8: Description | B8: Daily Contacts | C8: Monthly Toric | D8: Men's Aviator | E8: Women's Cat Eye | F8: Saline 300ml | G8: Intraocular Lens | H8: Phaco Tip
A9: Category | B9: Contact Lenses | C9: Contact Lenses | D9: Frames | E9: Frames | F9: Solutions | G9: Surgical | H9: Surgical
A10: Supplier | B10: ClearVision | C10: ClearVision | D10: OptiStyle | E10: OptiStyle | F10: AquaDrop | G10: MedEye Tech | H10: MedEye Tech
A11: Unit_Cost | B11: 12.5 | C11: 25 | D11: 45 | E11: 48.5 | F11: 4.25 | G11: 150 | H11: 85
A12: Lead_Time_Days | B12: 14 | C12: 21 | D12: 30 | E12: 30 | F12: 7 | G12: 45 | H12: 30
A13: Stock_Level | B13: 450 | C13: 120 | D13: 45 | E13: 180 | F13: 800 | G13: 15 | H13: 40
A14: Reorder_Point | B14: 500 | C14: 150 | D14: 50 | E14: 50 | F14: 400 | G14: 20 | H14: 25
A15: Total_Value | B15: 5625 | C15: 3000 | D15: 2025 | E15: 8730 | F15: 3400 | G15: 2250 | H15: 3400
A17: Table HLOOKUP
A18: SKU | B18: SURG-P-02 | C18: FRM-M-10 | D18: SURG-P-02 | E18: LENS-D-01 | F18: SURG-L-01 | G18: LENS-M-02
A19: Stock_Level | B19: =HLOOKUP(B18,A7:H15,7,FALSE) -> 40 | C19: =HLOOKUP(C18,B7:I15,7,FALSE) -> 45 | D19: =HLOOKUP(D18,C7:J15,7,FALSE) -> 40 | E19: =HLOOKUP(E18,A7:H15,7,FALSE) -> 450 | F19: =HLOOKUP(F18,G7:N15,7,FALSE) -> 15 | G19: =HLOOKUP(G18,A7:H15,7,FALSE) -> 120
A20: Lead_Time_Days | B20: =HLOOKUP(B18,A7:H15,6,FALSE) -> 30 | C20: =HLOOKUP(C18,B7:I15,6,FALSE) -> 30 | D20: =HLOOKUP(D18,C7:J15,6,FALSE) -> 30 | E20: =HLOOKUP(E18,A7:H15,6,FALSE) -> 14 | F20: =HLOOKUP(F18,G7:N15,6,FALSE) -> 45 | G20: =HLOOKUP(G18,A7:H15,6,FALSE) -> 21

Sheet inventory_transactions(countif)
A1: Order_ID | B1: Date | C1: SKU | D1: Qty_Sold | E1: Location | F1: Staff_ID | G1: Revenue | H1: Lead_Time | I1: Risk_Level | J1: Category | K1: Stock_Level
A2: ORD-501 | B2: 9/22/2025 | C2: SURG-P-02 | D2: 18 | E2: North | F2: Optician_A | G2: 1530 | H2: 30 | I2: Medium Risk | J2: =_xlfn.XLOOKUP('inventory_transactions(countif)'!C2,'product_masterlist(ifs)'!A:A,'product_masterlist(ifs)'!C:C,,0) -> Surgical | K2: =VLOOKUP(C2,'product_masterlist(ifs)'!A:I,7,FALSE) -> 40
A3: ORD-502 | B3: 8/16/2025 | C3: FRM-M-10 | D3: 4 | E3: North | F3: Optician_C | G3: 180 | H3: 30 | I3: Medium Risk | J3: =_xlfn.XLOOKUP(C3,'product_masterlist(ifs)'!A:A,'product_masterlist(ifs)'!C:C,"N/A",0) -> Frames | K3: =VLOOKUP(C3,'product_masterlist(ifs)'!A:I,7,FALSE) -> 45
A4: ORD-503 | B4: 45840 | C4: SURG-P-02 | D4: 13 | E4: East | F4: Optician_A | G4: 1105 | H4: 30 | I4: Medium Risk | J4: =_xlfn.XLOOKUP(C4,'product_masterlist(ifs)'!A:A,'product_masterlist(ifs)'!C:C,"N/A",0) -> Surgical | K4: =VLOOKUP(C4,'product_masterlist(ifs)'!A:I,7,FALSE) -> 40
A5: ORD-504 | B5: 45937 | C5: SURG-P-02 | D5: 16 | E5: West | F5: Surgeon_K | G5: 1360 | H5: 30 | I5: Medium Risk | J5: =_xlfn.XLOOKUP(C5,'product_masterlist(ifs)'!A:A,'product_masterlist(ifs)'!C:C,"N/A",0) -> Surgical | K5: =VLOOKUP(C5,'product_masterlist(ifs)'!A:I,7,FALSE) -> 40 | N5: Risk_Level | O5: Amount
A6: ORD-505 | B6: 5/29/2025 | C6: LENS-D-01 | D6: 7 | E6: West | F6: Optician_A | G6: 87.5 | H6: 14 | I6: Low Risk | J6: =_xlfn.XLOOKUP(C6,'product_masterlist(ifs)'!A:A,'product_masterlist(ifs)'!C:C,"N/A",0) -> Contact Lenses | K6: =VLOOKUP(C6,'product_masterlist(ifs)'!A:I,7,FALSE) -> 450 | N6: High Risk | O6: =COUNTIF(I:I,I8) -> 192
A7: ORD-506 | B7: 1/26/2025 | C7: SURG-P-02 | D7: 24 | E7: East | F7: Optician_B | G7: 2040 | H7: 30 | I7: Medium Risk | J7: =_xlfn.XLOOKUP(C7,'product_masterlist(ifs)'!A:A,'product_masterlist(ifs)'!C:C,"N/A",0) -> Surgical | K7: =VLOOKUP(C7,'product_masterlist(ifs)'!A:I,7,FALSE) -> 40
A8: ORD-507 | B8: 45999 | C8: SURG-L-01 | D8: 10 | E8: North | F8: Optician_C | G8: 1500 | H8: 45 | I8: High Risk | J8: =_xlfn.XLOOKUP(C8,'product_masterlist(ifs)'!A:A,'product_masterlist(ifs)'!C:C,"N/A",0) -> Surgical | K8: =VLOOKUP(C8,'product_masterlist(ifs)'!A:I,7,FALSE) -> 15
A9: ORD-508 | B9: 4/24/2025 | C9: LENS-D-01 | D9: 8 | E9: South | F9: Optician_C | G9: 100 | H9: 14 | I9: Low Risk | J9: =_xlfn.XLOOKUP(C9,'product_masterlist(ifs)'!A:A,'product_masterlist(ifs)'!C:C,"N/A",0) -> Contact Lenses | K9: =VLOOKUP(C9,'product_masterlist(ifs)'!A:I,7,FALSE) -> 450
A10: ORD-509 | B10: 5/21/2025 | C10: LENS-D-01 | D10: 3 | E10: South | F10: Optician_A | G10: 37.5 | H10: 14 | I10: Low Risk | J10: =_xlfn.XLOOKUP(C10,'product_masterlist(ifs)'!A:A,'product_masterlist(ifs)'!C:C,"N/A",0) -> Contact Lenses | K10: =VLOOKUP(C10,'product_masterlist(ifs)'!A:I,7,FALSE) -> 450
A11: ORD-510 | B11: 45699 | C11: LENS-M-02 | D11: 21 | E11: West | F11: Optician_C | G11: 525 | H11: 21 | I11: Medium Risk | J11: =_xlfn.XLOOKUP(C11,'product_masterlist(ifs)'!A:A,'product_masterlist(ifs)'!C:C,"N/A",0) -> Contact Lenses | K11: =VLOOKUP(C11,'product_masterlist(ifs)'!A:I,7,FALSE) -> 120 | N11: Risk_Level | O11: Location | P11: Amount
A12: ORD-511 | B12: 7/30/2025 | C12: LENS-D-01 | D12: 7 | E12: West | F12: Optician_B | G12: 87.5 | H12: 14 | I12: Low Risk | J12: =_xlfn.XLOOKUP(C12,'product_masterlist(ifs)'!A:A,'product_masterlist(ifs)'!C:C,"N/A",0) -> Contact Lenses | K12: =VLOOKUP(C12,'product_masterlist(ifs)'!A:I,7,FALSE) -> 450 | N12: High Risk | O12: West | P12: =COUNTIFS(I:I,N12,E:E,O12) -> 53
A13: ORD-512 | B13: 1/20/2025 | C13: LENS-D-01 | D13: 11 | E13: North | F13: Optician_A | G13: 137.5 | H13: 14 | I13: Low Risk | J13: =_xlfn.XLOOKUP(C13,'product_masterlist(ifs)'!A:A,'product_masterlist(ifs)'!C:C,"N/A",0) -> Contact Lenses | K13: =VLOOKUP(C13,'product_masterlist(ifs)'!A:I,7,FALSE) -> 450
A14: ORD-513 | B14: 45908 | C14: FRM-M-10 | D14: 8 | E14: East | F14: Optician_C | G14: 360 | H14: 30 | I14: Medium Risk | J14: =_xlfn.XLOOKUP(C14,'product_masterlist(ifs)'!A:A,'product_masterlist(ifs)'!C:C,"N/A",0) -> Frames | K14: =VLOOKUP(C14,'product_masterlist(ifs)'!A:I,7,FALSE) -> 45
A15: ORD-514 | B15: 46003 | C15: SURG-P-02 | D15: 25 | E15: South | F15: Optician_C | G15: 2125 | H15: 30 | I15: Medium Risk | J15: =_xlfn.XLOOKUP(C15,'product_masterlist(ifs)'!A:A,'product_masterlist(ifs)'!C:C,"N/A",0) -> Surgical | K15: =VLOOKUP(C15,'product_masterlist(ifs)'!A:I,7,FALSE) -> 40
A16: ORD-515 | B16: 45750 | C16: SURG-L-01 | D16: 1 | E16: East | F16: Optician_C | G16: 150 | H16: 45 | I16: High Risk | J16: =_xlfn.XLOOKUP(C16,'product_masterlist(ifs)'!A:A,'product_masterlist(ifs)'!C:C,"N/A",0) -> Surgical | K16: =VLOOKUP(C16,'product_masterlist(ifs)'!A:I,7,FALSE) -> 15
A17: ORD-516 | B17: 12/26/2025 | C17: SOL-S-01 | D17: 19 | E17: North | F17: Optician_A | G17: 80.75 | H17: 7 | I17: Low Risk | J17: =_xlfn.XLOOKUP(C17,'product_masterlist(ifs)'!A:A,'product_masterlist(ifs)'!C:C,"N/A",0) -> Solutions | K17: =VLOOKUP(C17,'product_masterlist(ifs)'!A:I,7,FALSE) -> 800
A18: ORD-517 | B18: 45757 | C18: SURG-L-01 | D18: 23 | E18: West | F18: Optician_B | G18: 3450 | H18: 45 | I18: High Risk | J18: =_xlfn.XLOOKUP(C18,'product_masterlist(ifs)'!A:A,'product_masterlist(ifs)'!C:C,"N/A",0) -> Surgical | K18: =VLOOKUP(C18,'product_masterlist(ifs)'!A:I,7,FALSE) -> 15 | N18: Location | O18: Amount
A19: ORD-518 | B19: 45845 | C19: FRM-M-10 | D19: 19 | E19: West | F19: Optician_B | G19: 855 | H19: 30 | I19: Medium Risk | J19: =_xlfn.XLOOKUP(C19,'product_masterlist(ifs)'!A:A,'product_masterlist(ifs)'!C:C,"N/A",0) -> Frames | K19: =VLOOKUP(C19,'product_masterlist(ifs)'!A:I,7,FALSE) -> 45 | N19: West | O19: =COUNTIF(E:E,N19) -> 364
A20: ORD-519 | B20: 5/22/2025 | C20: FRM-M-10 | D20: 16 | E20: South | F20: Optician_A | G20: 720 | H20: 30 | I20: Medium Risk | J20: =_xlfn.XLOOKUP(C20,'product_masterlist(ifs)'!A:A,'product_masterlist(ifs)'!C:C,"N/A",0) -> Frames | K20: =VLOOKUP(C20,'product_masterlist(ifs)'!A:I,7,FALSE) -> 45
A21: ORD-520 | B21: 4/28/2025 | C21: SURG-L-01 | D21: 6 | E21: South | F21: Optician_B | G21: 900 | H21: 45 | I21: High Risk | J21: =_xlfn.XLOOKUP(C21,'product_masterlist(ifs)'!A:A,'product_masterlist(ifs)'!C:C,"N/A",0) -> Surgical | K21: =VLOOKUP(C21,'product_masterlist(ifs)'!A:I,7,FALSE) -> 15 | N21: Location | O21: Risk_Level | P21: Amount
A22: ORD-521 | B22: 10/27/2025 | C22: LENS-M-02 | D22: 12 | E22: South | F22: Surgeon_K | G22: 300 | H22: 21 | I22: Medium Risk | J22: =_xlfn.XLOOKUP(C22,'product_masterlist(ifs)'!A:A,'product_masterlist(ifs)'!C:C,"N/A",0) -> Contact Lenses | K22: =VLOOKUP(C22,'product_masterlist(ifs)'!A:I,7,FALSE) -> 120 | N22: West | O22: High Risk | P22: =COUNTIFS(E:E,N22,I:I,O22) -> 53
A23: ORD-522 | B23: 45940 | C23: FRM-M-10 | D23: 19 | E23: West | F23: Optician_B | G23: 855 | H23: 30 | I23: Medium Risk | J23: =_xlfn.XLOOKUP(C23,'product_masterlist(ifs)'!A:A,'product_masterlist(ifs)'!C:C,"N/A",0) -> Frames | K23: =VLOOKUP(C23,'product_masterlist(ifs)'!A:I,7,FALSE) -> 45
A24: ORD-523 | B24: 11/13/2025 | C24: SURG-L-01 | D24: 2 | E24: East | F24: Optician_A | G24: 300 | H24: 45 | I24: High Risk | J24: =_xlfn.XLOOKUP(C24,'product_masterlist(ifs)'!A:A,'product_masterlist(ifs)'!C:C,"N/A",0) -> Surgical | K24: =VLOOKUP(C24,'product_masterlist(ifs)'!A:I,7,FALSE) -> 15 | R24: =P22/O19 -> 0.1456044
A25: ORD-524 | B25: 6/22/2025 | C25: LENS-M-02 | D25: 24 | E25: West | F25: Optician_C | G25: 600 | H25: 21 | I25: Medium Risk | J25: =_xlfn.XLOOKUP(C25,'product_masterlist(ifs)'!A:A,'product_masterlist(ifs)'!C:C,"N/A",0) -> Contact Lenses | K25: =VLOOKUP(C25,'product_masterlist(ifs)'!A:I,7,FALSE) -> 120
A26: ORD-525 | B26: 45717 | C26: SURG-L-01 | D26: 25 | E26: West | F26: Optician_B | G26: 3750 | H26: 45 | I26: High Risk | J26: =_xlfn.XLOOKUP(C26,'product_masterlist(ifs)'!A:A,'product_masterlist(ifs)'!C:C,"N/A",0) -> Surgical | K26: =VLOOKUP(C26,'product_masterlist(ifs)'!A:I,7,FALSE) -> 15
A27: ORD-526 | B27: 45787 | C27: LENS-D-01 | D27: 24 | E27: North | F27: Optician_A | G27: 300 | H27: 14 | I27: Low Risk | J27: =_xlfn.XLOOKUP(C27,'product_masterlist(ifs)'!A:A,'product_masterlist(ifs)'!C:C,"N/A",0) -> Contact Lenses | K27: =VLOOKUP(C27,'product_masterlist(ifs)'!A:I,7,FALSE) -> 450
A28: ORD-527 | B28: 4/21/2025 | C28: LENS-D-01 | D28: 18 | E28: South | F28: Optician_A | G28: 225 | H28: 14 | I28: Low Risk | J28: =_xlfn.XLOOKUP(C28,'product_masterlist(ifs)'!A:A,'product_masterlist(ifs)'!C:C,"N/A",0) -> Contact Lenses | K28: =VLOOKUP(C28,'product_masterlist(ifs)'!A:I,7,FALSE) -> 450
A29: ORD-528 | B29: 45725 | C29: LENS-D-01 | D29: 2 | E29: East | F29: Optician_B | G29: 25 | H29: 14 | I29: Low Risk | J29: =_xlfn.XLOOKUP(C29,'product_masterlist(ifs)'!A:A,'product_masterlist(ifs)'!C:C,"N/A",0) -> Contact Lenses | K29: =VLOOKUP(C29,'product_masterlist(ifs)'!A:I,7,FALSE) -> 450
A30: ORD-529 | B30: 2/17/2025 | C30: SOL-S-01 | D30: 9 | E30: South | F30: Optician_A | G30: 38.25 | H30: 7 | I30: Low Risk | J30: =_xlfn.XLOOKUP(C30,'product_masterlist(ifs)'!A:A,'product_masterlist(ifs)'!C:C,"N/A",0) -> Solutions | K30: =VLOOKUP(C30,'product_masterlist(ifs)'!A:I,7,FALSE) -> 800 | N30: {=_xlfn.UNIQUE(I:I)} -> Risk_Level | O30: Total | R30: East | S30: South | T30: West | U30: North
A31: ORD-530 | B31: 45911 | C31: SURG-P-02 | D31: 3 | E31: West | F31: Optician_B | G31: 255 | H31: 30 | I31: Medium Risk | J31: =_xlfn.XLOOKUP(C31,'product_masterlist(ifs)'!A:A,'product_masterlist(ifs)'!C:C,"N/A",0) -> Surgical | K31: =VLOOKUP(C31,'product_masterlist(ifs)'!A:I,7,FALSE) -> 40 | N31: Medium Risk | O31: =COUNTIF(I:I,N31) -> 805 | Q31: Medium Risk | R31: =COUNTIFS(I:I,"Medium Risk",E:E,R30) -> 190 | S31: =COUNTIFS(I:I,Q31,E:E,S30) -> 209 | T31: =COUNTIFS(I:I,Q31,E:E,T30) -> 206 | U31: =COUNTIFS(I:I,Q31,E:E,U30) -> 200
A32: ORD-531 | B32: 45698 | C32: SURG-L-01 | D32: 8 | E32: West | F32: Optician_C | G32: 1200 | H32: 45 | I32: High Risk | J32: =_xlfn.XLOOKUP(C32,'product_masterlist(ifs)'!A:A,'product_masterlist(ifs)'!C:C,"N/A",0) -> Surgical | K32: =VLOOKUP(C32,'product_masterlist(ifs)'!A:I,7,FALSE) -> 15 | N32: Low Risk | O32: =COUNTIF(I:I,N32) -> 418 | Q32: Low Risk | R32: =COUNTIFS(I:I,Q32,E:E,R30) -> 101 | S32: =COUNTIFS(I:I,Q32,E:E,S30) -> 111 | T32: =COUNTIFS(I:I,Q32,E:E,T30) -> 105 | U32: =COUNTIFS(I:I,Q32,E:E,U30) -> 101
A33: ORD-532 | B33: 45722 | C33: FRM-M-10 | D33: 9 | E33: North | F33: Surgeon_K | G33: 405 | H33: 30 | I33: Medium Risk | J33: =_xlfn.XLOOKUP(C33,'product_masterlist(ifs)'!A:A,'product_masterlist(ifs)'!C:C,"N/A",0) -> Frames | K33: =VLOOKUP(C33,'product_masterlist(ifs)'!A:I,7,FALSE) -> 45 | N33: High Risk | O33: =COUNTIF(I:I,N33) -> 192 | Q33: High Risk | R33: =COUNTIFS(I:I,Q33,E:E,R30) -> 44 | S33: =COUNTIFS(I:I,Q33,E:E,S30) -> 63 | T33: =COUNTIFS(I:I,Q33,E:E,T30) -> 53 | U33: =COUNTIFS(I:I,Q33,E:E,U30) -> 32
A34: ORD-533 | B34: 8/23/2025 | C34: SURG-L-01 | D34: 18 | E34: South | F34: Surgeon_K | G34: 2700 | H34: 45 | I34: High Risk | J34: =_xlfn.XLOOKUP(C34,'product_masterlist(ifs)'!A:A,'product_masterlist(ifs)'!C:C,"N/A",0) -> Surgical | K34: =VLOOKUP(C34,'product_masterlist(ifs)'!A:I,7,FALSE) -> 15 | N34: 0 | O34: =COUNTIF(I:I,N34) -> 0
A35: ORD-534 | B35: 45966 | C35: LENS-M-02 | D35: 7 | E35: East | F35: Optician_C | G35: 175 | H35: 21 | I35: Medium Risk | J35: =_xlfn.XLOOKUP(C35,'product_masterlist(ifs)'!A:A,'product_masterlist(ifs)'!C:C,"N/A",0) -> Contact Lenses | K35: =VLOOKUP(C35,'product_masterlist(ifs)'!A:I,7,FALSE) -> 120
A36: ORD-535 | B36: 1/31/2025 | C36: LENS-M-02 | D36: 6 | E36: North | F36: Optician_B | G36: 150 | H36: 21 | I36: Medium Risk | J36: =_xlfn.XLOOKUP(C36,'product_masterlist(ifs)'!A:A,'product_masterlist(ifs)'!C:C,"N/A",0) -> Contact Lenses | K36: =VLOOKUP(C36,'product_masterlist(ifs)'!A:I,7,FALSE) -> 120
A37: ORD-536 | B37: 45843 | C37: LENS-M-02 | D37: 21 | E37: West | F37: Surgeon_K | G37: 525 | H37: 21 | I37: Medium Risk | J37: =_xlfn.XLOOKUP(C37,'product_masterlist(ifs)'!A:A,'product_masterlist(ifs)'!C:C,"N/A",0) -> Contact Lenses | K37: =VLOOKUP(C37,'product_masterlist(ifs)'!A:I,7,FALSE) -> 120
A38: ORD-537 | B38: 45781 | C38: LENS-D-01 | D38: 24 | E38: South | F38: Optician_B | G38: 300 | H38: 14 | I38: Low Risk | J38: =_xlfn.XLOOKUP(C38,'product_masterlist(ifs)'!A:A,'product_masterlist(ifs)'!C:C,"N/A",0) -> Contact Lenses | K38: =VLOOKUP(C38,'product_masterlist(ifs)'!A:I,7,FALSE) -> 450 | N38: =_xlfn.XLOOKUP(O38,I:I,C:C,,0) -> SURG-L-01 | O38: High Risk | P38: =COUNTIFS(C:C,#REF!,I:I,O38) -> 0
A39: ORD-538 | B39: 10/31/2025 | C39: SURG-P-02 | D39: 6 | E39: South | F39: Optician_C | G39: 510 | H39: 30 | I39: Medium Risk | J39: =_xlfn.XLOOKUP(C39,'product_masterlist(ifs)'!A:A,'product_masterlist(ifs)'!C:C,"N/A",0) -> Surgical | K39: =VLOOKUP(C39,'product_masterlist(ifs)'!A:I,7,FALSE) -> 40
A40: ORD-539 | B40: 8/31/2025 | C40: FRM-W-12 | D40: 9 | E40: East | F40: Optician_B | G40: 436.5 | H40: 30 | I40: Medium Risk | J40: =_xlfn.XLOOKUP(C40,'product_masterlist(ifs)'!A:A,'product_masterlist(ifs)'!C:C,"N/A",0) -> Frames | K40: =VLOOKUP(C40,'product_masterlist(ifs)'!A:I,7,FALSE) -> 180
...
